<?xml version="1.0"?>
<robot name="demobot">
    <material name="black">
        <color rgba="0 0 0 1"/>
    </material>
    <material name="purple">
        <color rgba="0.3098 0.1765 0.4980 1" />
    </material>
    <material name="gray">
        <color rgba="0.5 0.5 0.5 1" />
    </material>

    <link name="base_link">
        <visual>
            <geometry>
                <box size="0.2 0.2 0.005"/>
            </geometry>
            <material name="purple"/>
        </visual>
    </link>

    <joint name="caster joint" type="fixed">
        <parent link="base_link"/>
        <child link="caster"/>
        <origin xyz="-0.09 0 -0.03"/>
    </joint>

    <link name="caster">
        <visual>
            <geometry>
                <sphere radius="0.01"/>
            </geometry>
            <material name="gray"/>
        </visual>
    </link>

    <joint name="left_wheel_joint" type="continuous">
        <parent link="base_link"/>
        <child link="left_wheel"/>
        <origin xyz="0.075 0.115 -0.01" rpy="1.571 0 0"/>
        <axis xyz="0 0 1"/>
    </joint>

    <link name="left_wheel">
        <visual>
            <geometry>
                <cylinder radius="0.03" length="0.025"/>
            </geometry>
            <material name="black"/>
        </visual>
    </link>

    <joint name="right_wheel_joint" type="continuous">
        <parent link="base_link"/>
        <child link="right_wheel"/>
        <origin xyz="0.075 -0.115 -0.01" rpy="1.571 0 0"/>
        <axis xyz="0 0 1"/>
    </joint>

    <link name="right_wheel">
        <visual>
            <geometry>
                <cylinder radius="0.03" length="0.025"/>
            </geometry>
            <material name="black"/>
        </visual>
    </link>

</robot>