<?xml version="1.0"?>
<robot xmlns:xacro="http://www.ros.org/wiki/xacro" name="demobot">
    <xacro:include filename="materials.xacro" />

    <!-- Constants -->
    <xacro:property name="PI" value="3.14159265359" />

    <xacro:property name="BASE_X" value="1.0" />
    <xacro:property name="BASE_Y" value="0.8" />
    <xacro:property name="BASE_Z" value="0.4" />
    
    <xacro:property name="CASTER_OFF_X" value="-0.4" />
    <xacro:property name="CASTER_OFF_Z" value="-0.2" />
    <xacro:property name="CASTER_R" value="0.1" />

    <xacro:property name="WHEEL_OFF_X" value="0.2" />
    <xacro:property name="WHEEL_OFF_Y" value="0.5" />
    <xacro:property name="WHEEL_R" value="0.3" />
    <xacro:property name="WHEEL_L" value="0.1" />

    <!-- Wheel macro -->
    <xacro:macro name="Wheel" params="prefix y_reflect">
        <joint name="${prefix}_wheel_joint" type="continuous">
            <parent link="base_link" />
            <child link="${prefix}_wheel_link" />
            <origin xyz="${WHEEL_OFF_X} ${y_reflect*WHEEL_OFF_Y} 0" rpy="${PI/2} 0 0" />
            <axis xyz="0 0 1" />
        </joint>

        <link name="${prefix}_wheel_link">
            <visual>
                <geometry>
                    <cylinder radius="${WHEEL_R}" length="${WHEEL_L}" />
                </geometry>
                <material name="black" />
            </visual>
        </link>
    </xacro:macro>

    <!-- Start Modelling -->
    <link name="base_link">
        <visual>
            <geometry>
                <box size="${BASE_X} ${BASE_Y} ${BASE_Z}"/>
            </geometry>
            <material name="purple"/>
        </visual>
    </link>

    <joint name="caster_joint" type="fixed">
        <parent link="base_link"/>
        <child link="caster_ball"/>
        <origin xyz="${CASTER_OFF_X} 0 ${CASTER_OFF_Z}"/>
    </joint>

    <link name="caster_ball">
        <visual>
            <geometry>
                <sphere radius="${CASTER_R}"/>
            </geometry>
            <material name="gray"/>
        </visual>
    </link>

    <xacro:Wheel prefix="left" y_reflect="1" />
    <xacro:Wheel prefix="right" y_reflect="-1" />

</robot>

